Workbook

Sheet Guide
A1: SELA progress tracker
A2: Data as of 2026-09-23. Generated from docs/tracking/tracker.json and docs/FSD_Sela.md; do not edit this workbook by hand.
A3: To update: edit tracker.json, then run `python scripts/build_tracker.py` (see docs/tracking/README.md).
A5: Task statuses
A6: Not Started: nothing committed for the task.
A7: In Progress: RED test committed or work under way.
A8: Pending Verification: implemented, but a stated verification step is still open (for example against real infrastructure).
A9: Completed: RED and GREEN commits recorded, coverage >= 80% where applicable, scripts/check.sh passes, docs synced.
A11: Requirement statuses (Traceability sheet): Not Started, Partial, Completed.
A12: Sheets: Summary (live counts), Tracker (one row per task and module), Change Log, Traceability (FR IDs).

Sheet Summary
A1: Phase / Milestone | B1: Not Started | C1: In Progress | D1: Pending Verification | E1: Completed | F1: Total | G1: % Completed
A2: Milestone 1: Host creates an event | B2: =COUNTIFS(Tracker!$A:$A,$A2,Tracker!$E:$E,B$1) | C2: =COUNTIFS(Tracker!$A:$A,$A2,Tracker!$E:$E,C$1) | D2: =COUNTIFS(Tracker!$A:$A,$A2,Tracker!$E:$E,D$1) | E2: =COUNTIFS(Tracker!$A:$A,$A2,Tracker!$E:$E,E$1) | F2: =SUM(B2:E2) | G2: =IF(F2=0,0,E2/F2)
A3: Milestone 2: Guest captures and uploads | B3: =COUNTIFS(Tracker!$A:$A,$A3,Tracker!$E:$E,B$1) | C3: =COUNTIFS(Tracker!$A:$A,$A3,Tracker!$E:$E,C$1) | D3: =COUNTIFS(Tracker!$A:$A,$A3,Tracker!$E:$E,D$1) | E3: =COUNTIFS(Tracker!$A:$A,$A3,Tracker!$E:$E,E$1) | F3: =SUM(B3:E3) | G3: =IF(F3=0,0,E3/F3)
A4: Milestone 3: Role-correct gallery | B4: =COUNTIFS(Tracker!$A:$A,$A4,Tracker!$E:$E,B$1) | C4: =COUNTIFS(Tracker!$A:$A,$A4,Tracker!$E:$E,C$1) | D4: =COUNTIFS(Tracker!$A:$A,$A4,Tracker!$E:$E,D$1) | E4: =COUNTIFS(Tracker!$A:$A,$A4,Tracker!$E:$E,E$1) | F4: =SUM(B4:E4) | G4: =IF(F4=0,0,E4/F4)
A5: Milestone 4: Moderate and export | B5: =COUNTIFS(Tracker!$A:$A,$A5,Tracker!$E:$E,B$1) | C5: =COUNTIFS(Tracker!$A:$A,$A5,Tracker!$E:$E,C$1) | D5: =COUNTIFS(Tracker!$A:$A,$A5,Tracker!$E:$E,D$1) | E5: =COUNTIFS(Tracker!$A:$A,$A5,Tracker!$E:$E,E$1) | F5: =SUM(B5:E5) | G5: =IF(F5=0,0,E5/F5)
A6: Milestone 5: Plans and payment | B6: =COUNTIFS(Tracker!$A:$A,$A6,Tracker!$E:$E,B$1) | C6: =COUNTIFS(Tracker!$A:$A,$A6,Tracker!$E:$E,C$1) | D6: =COUNTIFS(Tracker!$A:$A,$A6,Tracker!$E:$E,D$1) | E6: =COUNTIFS(Tracker!$A:$A,$A6,Tracker!$E:$E,E$1) | F6: =SUM(B6:E6) | G6: =IF(F6=0,0,E6/F6)
A7: Milestone 6: Privacy and compliance readiness | B7: =COUNTIFS(Tracker!$A:$A,$A7,Tracker!$E:$E,B$1) | C7: =COUNTIFS(Tracker!$A:$A,$A7,Tracker!$E:$E,C$1) | D7: =COUNTIFS(Tracker!$A:$A,$A7,Tracker!$E:$E,D$1) | E7: =COUNTIFS(Tracker!$A:$A,$A7,Tracker!$E:$E,E$1) | F7: =SUM(B7:E7) | G7: =IF(F7=0,0,E7/F7)
A8: Milestone 7: Closed beta | B8: =COUNTIFS(Tracker!$A:$A,$A8,Tracker!$E:$E,B$1) | C8: =COUNTIFS(Tracker!$A:$A,$A8,Tracker!$E:$E,C$1) | D8: =COUNTIFS(Tracker!$A:$A,$A8,Tracker!$E:$E,D$1) | E8: =COUNTIFS(Tracker!$A:$A,$A8,Tracker!$E:$E,E$1) | F8: =SUM(B8:E8) | G8: =IF(F8=0,0,E8/F8)
A9: Milestone 8: RBAC foundation (cross-cutting platform work) | B9: =COUNTIFS(Tracker!$A:$A,$A9,Tracker!$E:$E,B$1) | C9: =COUNTIFS(Tracker!$A:$A,$A9,Tracker!$E:$E,C$1) | D9: =COUNTIFS(Tracker!$A:$A,$A9,Tracker!$E:$E,D$1) | E9: =COUNTIFS(Tracker!$A:$A,$A9,Tracker!$E:$E,E$1) | F9: =SUM(B9:E9) | G9: =IF(F9=0,0,E9/F9)
A10: Backlog: Should-have and later phases | B10: =COUNTIFS(Tracker!$A:$A,$A10,Tracker!$E:$E,B$1) | C10: =COUNTIFS(Tracker!$A:$A,$A10,Tracker!$E:$E,C$1) | D10: =COUNTIFS(Tracker!$A:$A,$A10,Tracker!$E:$E,D$1) | E10: =COUNTIFS(Tracker!$A:$A,$A10,Tracker!$E:$E,E$1) | F10: =SUM(B10:E10) | G10: =IF(F10=0,0,E10/F10)
A11: All tasks | B11: =SUM(B2:B10) | C11: =SUM(C2:C10) | D11: =SUM(D2:D10) | E11: =SUM(E2:E10) | F11: =SUM(F2:F10) | G11: =IF(F11=0,0,E11/F11)
A13: Requirements (FR IDs) | B13: Not Started | C13: Partial | D13: Completed | E13: Total
A14: All FR IDs | B14: =COUNTIF(Traceability!$E:$E,B13) | C14: =COUNTIF(Traceability!$E:$E,C13) | D14: =COUNTIF(Traceability!$E:$E,D13) | E14: =SUM(B14:D14)

Sheet Tracker
A1: Phase / Milestone | B1: Task ID | C1: Task & Description | D1: Module / Service | E1: Status | F1: TDD: RED commit | G1: TDD: GREEN commit | H1: Test coverage | I1: FR IDs | J1: Key Deliverables / Artifacts | K1: Last Updated
A2: Milestone 1: Host creates an event | B2: T1.1 | C2: Task 1: Scaffold & Tooling — Go API skeleton: JSON response envelope, health endpoint, API entrypoint | D2: internal/httpx, internal/health, cmd/api | E2: Completed | F2: aae2ee6 | G2: bbc37ea 0bd97a3 | H2: 100% | J2: httpx.WriteSuccess/WriteError ({success,data,error}); GET /healthz; graceful-shutdown server (later replaced by T3.7) | K2: 2026-09-19
A3: Milestone 1: Host creates an event | B3: T1.2 | C3: Task 1: Scaffold & Tooling — SvelteKit web app scaffold with Vitest and the client-side API envelope parser | D3: apps/web | E3: Completed | F3: 5fa9976 | G3: 4443ea5 | H3: 100% lines / 91.7% branches | J3: apps/web (Svelte 5, Vite 8); src/lib/api/envelope.ts with ApiError; Vitest with an 80% coverage threshold; svelte-check clean | K3: 2026-09-19
A4: Milestone 1: Host creates an event | B4: T1.3 | C4: Task 1: Scaffold & Tooling — Local dev infrastructure and the validation script | D4: deploy, scripts/check.sh | E4: Completed | F4: n/a (tooling) | G4: 20ade0e cbeb530 | H4: n/a | J4: deploy/docker-compose.yml (Postgres, Redis, Mailpit, localhost-only); .env.example; scripts/check.sh; CLAUDE.md commands | K4: 2026-09-19
A5: Milestone 1: Host creates an event | B5: T2.1 | C5: Task 2: Schema & Category Presets — Migration runner and the hosts, event_categories and events schema | D5: internal/db (migrations 0001-0003) | E5: Completed | F5: 9fe108b | G5: 45b058c b0b5b25 | H5: 94.7% | I5: FR-01.1, FR-01.2, FR-01.3, FR-01.4 | J5: goose runner (db.Up/db.Down); tables with constraints and indexes; six seeded categories with undefined defaults stored as 'tbd'; internal/testdb (fresh database per test) | K5: 2026-09-19
A6: Milestone 1: Host creates an event | B6: T3.1 | C6: Task 3: Email OTP Auth for Hosts — cmd/migrate CLI to apply or revert SQL migrations | D6: cmd/migrate | E6: Completed | F6: f5935c9 | G6: a1e047f b2ef0ef | H6: 80.6% | J6: go run ./cmd/migrate [up|down] reading DATABASE_URL; run(ctx, args, getenv, out) is unit-testable | K6: 2026-09-19
A7: Milestone 1: Host creates an event | B7: T3.2 | C7: Task 3: Email OTP Auth for Hosts — Restructure the Go backend under apps/api | D7: apps/api (all Go code) | E7: Completed | F7: n/a (pure move; existing tests unchanged) | G7: aebe62e | H7: unchanged (all packages) | J7: go.mod moved to apps/api (module path unchanged); cmd, internal moved; db became internal/db; scripts/check.sh runs Go steps in apps/api | K7: 2026-09-19
A8: Milestone 1: Host creates an event | B8: T3.3 | C8: Task 3: Email OTP Auth for Hosts — gRPC contracts and the proto generation script | D8: api/proto/v1, gen/go, scripts/proto-gen.sh | E8: Completed | F8: 409a125 | G8: 24c7281 | H8: n/a (generated code) | I8: FR-09.1 | J8: auth.proto (implemented) and event.proto (contract only); buf.yaml, buf.gen.yaml; committed gen/go; proto-gen.sh --check drift detection wired into check.sh | K8: 2026-09-19
A9: Milestone 1: Host creates an event | B9: T3.4 | C9: Task 3: Email OTP Auth for Hosts — Environment configuration with validation and secret redaction | D9: internal/config | E9: Completed | F9: 730db37 | G9: 3b1ab82 | H9: 100% | J9: config.Load(getenv) reports every problem at once, never echoes secret values; Config.String() redacts secrets | K9: 2026-09-19
A10: Milestone 1: Host creates an event | B10: T3.5 | C10: Task 3: Email OTP Auth for Hosts — Auth core: OTP lifecycle, Redis state, Postgres hosts, SMTP mailer, sessions | D10: services/auth | E10: Completed | F10: 1043ded | G10: 3c45e13 | H10: 80.2% at this commit (84.6% package total after T3.6) | I10: FR-09.1, FR-SEC.9, FR-SEC.4 | J10: 6-digit code stored as HMAC with 5 min TTL, single use; per-email and per-client rate limits; lockout after 5 wrong attempts for 15 min; hashed 12 h sessions; Postgres find-or-create host; SMTP mailer with header-injection guards | K10: 2026-09-19
A11: Milestone 1: Host creates an event | B11: T3.6 | C11: Task 3: Email OTP Auth for Hosts — HTTP and gRPC adapters and the RequireHost middleware | D11: services/auth | E11: Completed | F11: ffed71f | G11: ce4729e | H11: 84.6% | I11: FR-09.1, FR-SEC.4, FR-SEC.9 | J11: POST /api/v1/auth/otp/request and /verify; HttpOnly SameSite=Lax session cookie, token never in a body; Retry-After on 429; X-Forwarded-For ignored; sela.auth.v1.AuthService server; RequireHost + HostID(ctx) | K11: 2026-09-19
A12: Milestone 1: Host creates an event | B12: T3.7 | C12: Task 3: Email OTP Auth for Hosts — Wire config, Postgres, Redis, SMTP and auth into the API with an end-to-end test | D12: cmd/api | E12: Completed | F12: 5a3dbe0 578bab2 | G12: 2bffd81 218243d | H12: 81.7% | I12: FR-09.1 | J12: HTTP :8080 + gRPC :9090 in one process; run(ctx, getenv) with graceful shutdown; end-to-end test over HTTP and gRPC against real Postgres, in-process Redis and SMTP; .env.example documents the variables | K12: 2026-09-19
A13: Milestone 1: Host creates an event | B13: T3.8 | C13: Task 3: Email OTP Auth for Hosts — Verify against the real docker-compose Redis and Mailpit (Docker was not running during development) | D13: deploy, cmd/api | E13: Completed | F13: n/a | G13: n/a | H13: n/a | I13: FR-09.1 | J13: Verified live on 2026-09-20 against docker compose Redis 7 (password) and Mailpit with the real cmd/api, via apps/web/tests/e2e/auth-live.spec.ts (6 checks, all pass, no service change needed) and the host happy path (sign-in read from the Mailpit inbox). Checked: email delivery and format, wrong/right code, cookie flags, no token in body, single use, hashes-only in Redis, rate limit (429 + Retry-After), lockout after 5 wrong codes. | K13: 2026-09-20
A14: Milestone 1: Host creates an event | B14: T3.9 | C14: Task 3: Email OTP Auth for Hosts — Docs sync and this progress tracker | D14: docs (FSD v2.5), docs/tracking | E14: Completed | F14: n/a (documentation) | G14: n/a (docs/ is gitignored, not committed) | H14: n/a | J14: FSD v2.5 (2.6, 4.9 note, 5 notes, 6 endpoints and gRPC, 8.6 parameters, 11.1 status); SELA_Progress_Tracker.xlsx and its build script scripts/build_tracker.py | K14: 2026-09-19
A15: Milestone 1: Host creates an event | B15: T3.10 | C15: Task 3: Email OTP Auth for Hosts — Session logout/revocation endpoint and refresh token (remainder of FR-SEC.4) | D15: services/auth | E15: Not Started | I15: FR-SEC.4 | J15: Revocable sessions exposed through an endpoint; decide whether a refresh token is still needed | K15: 2026-09-19
A16: Milestone 1: Host creates an event | B16: T4.1 | C16: Task 4: Event Service — Event domain: category presets with fallback defaults, event creation, short code and QR (PNG/SVG), host-scoped retrieval | D16: services/event (service, postgres repository, qr) | E16: Completed | F16: acbece7 | G16: b726530 | H16: 90.9% | I16: FR-01.1, FR-01.2, FR-01.3, FR-01.4 | J16: Effective defaults (host override, then defined category default, then unlimited/instant fallback); validation; 8-char base62 short codes with collision retry; 256-bit access token never returned; QR that decodes back to the short link (verified with a real decoder); reads filter by event_id AND host_id | K16: 2026-09-20
A17: Milestone 1: Host creates an event | B17: T4.2 | C17: Task 4: Event Service — HTTP and gRPC adapters and their wiring into cmd/api | D17: services/event (http, grpc), cmd/api | E17: Completed | F17: 6c65e04 aeb1251 | G17: 094e6bb cb7f51b 51a1ef0 | H17: 90.9% (services/event), 82.7% (cmd/api) | I17: FR-01.1, FR-01.2, FR-01.3, FR-01.4 | J17: GET /api/v1/event-categories (public); POST /api/v1/events, GET /api/v1/events/{id}, GET .../qr.png and qr.svg behind RequireHost; sela.event.v1.EventService behind the Bearer interceptor; end-to-end test over HTTP and gRPC including a second host getting 404 | K17: 2026-09-20
A18: Milestone 1: Host creates an event | B18: T4.3 | C18: Task 4: Event Service — Supporting infrastructure: shared JSON decoder, SHORT_LINK_BASE_URL, event proto extension, gRPC host interceptor | D18: internal/httpx, internal/config, api/proto/v1/event.proto, services/auth | E18: Completed | F18: 0a61dd6 1c9b2a8 6f8cf8e b1a51e3 | G18: 3861ee6 1110a02 ff5ae81 da51888 | H18: 100% (httpx), 100% (config), 85.1% (auth) | I18: FR-01.3, FR-SEC.4 | J18: httpx.DecodeJSON (auth refactored onto it); required SHORT_LINK_BASE_URL (decision D4); Event.short_link/qr URLs and EventCategory effective_* fields; NewUnaryHostInterceptor with deny-by-default and a public allowlist | K18: 2026-09-20
A19: Milestone 1: Host creates an event | B19: T4.4 | C19: Task 4: Event Service — Docs sync (FSD v2.6) and tracker update for Task 4 | D19: docs (FSD v2.6), docs/tracking | E19: Completed | F19: n/a (documentation) | G19: n/a (docs/ is gitignored, not committed) | H19: n/a | J19: FSD 4.1 implementation notes, 6 endpoints and gRPC, 11.1 status; this tracker | K19: 2026-09-20
A20: Milestone 1: Host creates an event | B20: T5.1 | C20: Task 5: QR code and short link — Short-link resolver: GET /e/{short_code} (QR generation and the configurable base URL were delivered in T4.1 to T4.3) | D20: services/event | E20: Completed | F20: 1c6b579 1c6fa33 e8c01ae bebb849 | G20: 4a9208e 97bdbe1 0e537e9 | H20: 91.3% | I20: FR-01.3 | J20: Resolver for short links to a placeholder guest page until the guest camera exists (Milestone 2) | K20: 2026-09-19
A21: Milestone 1: Host creates an event | B21: T6.1 | C21: Task 6: Host web flow — Sign-in, category picker, name and date form, result screen with QR and link | D21: apps/web | E21: Completed | F21: e22fc04 abfcf99 deb9be8 d205277 d1100f0 1d11def 7e82db3 63cce8a | G21: 840a9e6 9718420 a625187 532c966 94f617f 41bd0e7 1b66d55 e89ee60 | H21: 99.7% lines, 90.2% branches, 96.8% statements, 97% functions (151 tests, 13 files) | I21: FR-01.1, FR-01.2, FR-01.3, FR-09.1 | J21: Routes /auth/login (two-step email OTP), /events/new (category picker, name/date form, read-only WIB, collapsed advanced overrides), /events/[id] (short link with copy, QR image, PNG/SVG download); SPA (ssr off), same-origin /api Vite dev proxy, Indonesian mobile-first paper-and-ink design. Tooling commit 64bb0d2; test-only fix 2185cb4. Verified in a real browser against a stub API only: Redis/Mailpit were unavailable, so sign-in against the real API is still unverified (see T3.8). | K21: 2026-09-20
A22: Milestone 1: Host creates an event | B22: T6.2 | C22: Task 6: Host web flow — Docs sync (FSD v2.8) and tracker update for Task 6 | D22: docs (FSD v2.8), docs/tracking | E22: Completed | F22: n/a (documentation) | G22: n/a (docs/ is gitignored, not committed) | H22: n/a | J22: FSD 10.1 implementation note, change row, 11.1 status; this tracker | K22: 2026-09-20
A23: Milestone 1: Host creates an event | B23: T7.1 | C23: Task 7: Verify milestone outcome — Real-stack end-to-end test and automated timing against the 3-minute target (the human timing is T7.2) | D23: apps/web (tests/e2e), scripts/e2e.sh, scripts/check.sh | E23: Completed | F23: 56159ff 70c75d0 44e0983 | G23: 29d31b5 fcdfe29 6037092 96d0a2a 7b11984 | H23: n/a for e2e; helper unit tests 17 (168 unit tests total, web coverage 99.7% lines / 90.2% branches); 10 e2e tests pass on the real stack | I23: FR-01.1, FR-01.2, FR-01.3, FR-09.1 | J23: Playwright (installed Chrome) against real cmd/api + Postgres + Redis + Mailpit via scripts/e2e.sh, also run by scripts/check.sh: sign-in from the Mailpit inbox, category, form, event, short link, QR PNG decoded back to the link, PNG/SVG downloads, cookie flags, guest resolver, reload, not-found, signed-out bounce. Scripted setup time 2.7-2.8 s warm (8.5 s cold first run) vs the 180 s target. Tooling commits 58b435f, d34c798. | K23: 2026-09-20
A24: Milestone 1: Host creates an event | B24: T7.2 | C24: Task 7: Verify milestone outcome — Human timed usability check: median setup time of 3-5 first-time hosts against the PRD metric (3 minutes or less, no documentation) | D24: docs/tracking (usability_sessions.csv) | E24: Pending Verification | F24: n/a | G24: n/a | H24: n/a | I24: FR-01.1, FR-01.2, FR-01.3 | J24: Protocol in docs/tracking/README.md and an empty session template docs/tracking/usability_sessions.csv exist; no sessions have been run. Needs 3-5 first-time hosts; the median of total_s is compared with 180 s and recorded in the PRD metrics table. Automation (T7.1) cannot stand in for it. | K24: 2026-09-20
A25: Milestone 1: Host creates an event | B25: T7.3 | C25: Task 7: Verify milestone outcome — Docs sync (FSD v2.9) and tracker update for Task 7 | D25: docs (FSD v2.9), docs/tracking, CLAUDE.md | E25: Completed | F25: n/a (documentation) | G25: n/a (FSD/CLAUDE.md are gitignored .md files; the tracker files are versioned) | H25: n/a | J25: FSD change row, 8.6 live-verification note, 10.1 e2e/timing note, 11.1; tracking README timed-check protocol; this tracker | K25: 2026-09-20
A26: Milestone 2: Guest captures and uploads | B26: M2.1 | C26: Milestone 2 (not yet planned) — Guest scan, camera, upload with quota, gallery upload | D26: apps/web, services/media, services/event | E26: Not Started | I26: FR-02.1-02.4, FR-03.1-03.6, FR-04.1-04.2, FR-SEC.2, FR-SEC.3 | J26: Guest session, PWA camera pipeline, Redis shot quota, upload validation | K26: 2026-09-19
A27: Milestone 3: Role-correct gallery | B27: M3.1 | C27: Milestone 3 (not yet planned) — Role-correct gallery, reveal timer, real-time channels | D27: services/gallery, services/realtime | E27: Not Started | I27: FR-05.1-05.6 | J27: Host sees all media, guest only their own, WebSocket channels split by role | K27: 2026-09-19
A28: Milestone 4: Moderate and export | B28: M4.1 | C28: Milestone 4 (not yet planned) — Moderation and full-gallery ZIP export | D28: services/gallery, services/media | E28: Not Started | I28: FR-06.1-06.4, FR-07.1-07.3 | J28: Hide/delete, asynchronous ZIP export, share links | K28: 2026-09-19
A29: Milestone 5: Plans and payment | B29: M5.1 | C29: Milestone 5 (not yet planned) — Plans, package recommendation and payment (QRIS, e-wallet, card) | D29: services/payment, services/event | E29: Not Started | I29: FR-01.5, FR-01.6, FR-09.2, FR-09.3 | J29: Free and paid tiers by event scale; micro-payments; transaction history | K29: 2026-09-19
A30: Milestone 6: Privacy and compliance readiness | B30: M6.1 | C30: Milestone 6 (not yet planned) — Privacy and compliance readiness | D30: cross-cutting | E30: Not Started | I30: FR-SEC.1, FR-SEC.5-SEC.8, FR-SEC.10 | J30: PII column encryption with a blind index, audit log, retention and deletion, child-event defaults, noindex headers | K30: 2026-09-19
A31: Milestone 7: Closed beta | B31: M7.1 | C31: Milestone 7 (not yet planned) — Closed beta across wedding, graduation and birthday events | D31: operations | E31: Not Started | J31: Validate the hypothesis and fill the TBD success metrics in the PRD | K31: 2026-09-19
A32: Milestone 8: RBAC foundation (cross-cutting platform work) | B32: T9.1 | C32: Task 9: RBAC foundation — RBAC schema (roles, menus, dropdowns, actions/permissions) and the services/rbac backend package; events:create gated on the already-shipped create-event route | D32: internal/db (0004, 0005), services/rbac, services/event, cmd/api | E32: Completed | F32: 85ac425 e76992d 08d0812 68ae150 | G32: cf5f3a8 b85cbb8 1bc1ec4 bb79173 | H32: services/rbac 81.9%; services/event 91.3%; cmd/api 83.3% | J32: migrations 0004_rbac_foundation.sql, 0005_hosts_role_and_preferences.sql; services/rbac (types/postgres/service/http) with GET /api/v1/auth/me and PATCH /api/v1/me/preferences; RequirePermission wired onto POST /api/v1/events (events:create); seed limited to 2 menus (events_new, settings) and 2 enforced permissions (events:create, profile:update), every existing host granted both so no current behavior changes | K32: 2026-09-23
A33: Milestone 8: RBAC foundation (cross-cutting platform work) | B33: T9.2 | C33: Task 9: RBAC foundation — Frontend: rbac API client, best-effort profile fetch in the root layout, dynamic Nav, dark theme palette, and the new /settings page with real EN/ID switching | D33: apps/web | E33: Completed | F33: 14bc5fe 6dea65a 4be3c95 | G33: 21fbdb5 e1cb469 23963e0 d98a473 694ba26 99c2c86 | H33: 184 tests pass; 97.16% statements / 89.65% branches / 97.6% functions / 99.75% lines; svelte-check 0 errors/0 warnings | J33: src/lib/api/rbac.ts; src/lib/components/Nav.svelte; :root[data-theme='dark'] palette in tokens.css; +layout.ts best-effort getProfile() (swallows a 401 so /auth/login never breaks); +layout.svelte renders Nav and sets document.documentElement.dataset.theme; src/routes/settings/+page.svelte (role, theme toggle, language toggle, own local EN/ID string table); the three pre-existing host pages keep their hardcoded Indonesian text unchanged | K33: 2026-09-23
A34: Milestone 8: RBAC foundation (cross-cutting platform work) | B34: T9.3 | C34: Task 9: RBAC foundation — Real-stack verification and docs/tracking sync for Task 8 | D34: docs, docs/tracking, CLAUDE.md | E34: Completed | F34: n/a (documentation) | G34: n/a (docs/ is gitignored, not committed) | H34: n/a | J34: scripts/check.sh run against Docker Redis+Mailpit and a local Postgres (proto-gen --check, gofmt/vet/lint, go test -cover, svelte-check, vitest coverage, real-stack Playwright e2e); FSD 3.5/5/6/8.6/10.1/11.1 updates; CLAUDE.md bullets for services/rbac and the two new frontend surfaces; this tracker | K34: 2026-09-23
A35: Backlog: Should-have and later phases | B35: BL.1 | C35: Backlog: Notifications — Scheduled and transactional email/WhatsApp notifications | D35: services/notification | E35: Not Started | I35: FR-08.1-08.2 | J35: Event reminders, reveal notices, expiry warnings | K35: 2026-09-19
A36: Backlog: Should-have and later phases | B36: BL.2 | C36: Backlog: Hall of Fame — Host-curated highlights visible to guests | D36: services/gallery | E36: Not Started | I36: FR-11.1-11.5 | J36: Curation, ordering and sharing of the best photos | K36: 2026-09-19
A37: Backlog: Should-have and later phases | B37: BL.3 | C37: Backlog: Personal/Instant Mode (v1.1) — Capture without an event and send results to several recipients | D37: apps/web, services/media | E37: Not Started | I37: FR-10.1-10.7 | J37: Deferred until Event Mode is stable | K37: 2026-09-19

Sheet Change Log
A1: Phase / Milestone | B1: Module / Service | C1: Task ID | D1: Summary of implemented functionality | E1: Breaking changes / structural refactors | F1: Deviations & technical decisions | G1: Commits | H1: Date
A2: Milestone 1: Host creates an event | B2: api/proto/v1, gen/go | C2: T3.3 | D2: Added auth.proto and event.proto, buf configuration and scripts/proto-gen.sh with a --check drift mode. | E2: New build-time requirement: buf, protoc-gen-go and protoc-gen-go-grpc are needed to regenerate; check.sh now fails on stale generated code. | F2: Separate proto packages (sela.auth.v1, sela.event.v1) share one directory, so buf lint exceptions PACKAGE_DIRECTORY_MATCH and DIRECTORY_SAME_PACKAGE were added. event.proto is contract only. CreateEventRequest has no host_id: ownership comes from the session. | G2: 409a125 24c7281 | H2: 2026-09-19
A3: Milestone 1: Host creates an event | B3: apps/api (structure) | C3: T3.2 | D3: Moved all Go backend code under apps/api and moved go.mod there with the module path unchanged. | E3: STRUCTURAL: cmd/, internal/ and go.mod moved to apps/api; the db package became internal/db (import path github.com/Briyantama/SELA/internal/db). Go commands must now run from apps/api; scripts/check.sh updated. | F3: Migrations live inside internal/db because Go embed cannot reference parent directories. Refactor verified by all existing tests passing unchanged. | G3: aebe62e | H3: 2026-09-19
A4: Milestone 1: Host creates an event | B4: apps/web | C4: T1.2 | D4: Scaffolded SvelteKit with Vitest (80% threshold) and an envelope parser mirroring the Go envelope. | E4: None. | F4: npm instead of pnpm (pnpm not installed); Node >= 20.19 required by Vite 8, so a newer Node is prepended to PATH per command. 3 low-severity npm audit findings (transitive cookie) left unfixed because the suggested fix is a breaking downgrade. | G4: 5fa9976 4443ea5 | H4: 2026-09-19
A5: Milestone 1: Host creates an event | B5: apps/web | C5: T6.1 | D5: Built the host web flow: /auth/login (email OTP), /events/new (category picker, details, collapsed overrides), /events/[id] (short link, QR, downloads); API client with credentials, timeout, status and Retry-After; jsdom component tests; /api dev proxy. | E5: None for the API. The web app is now a client-side SPA (ssr off) and expects /api on its own origin (Vite proxy in dev; a reverse proxy is needed in deployment). | F5: Time zone is a read-only WIB label because POST /api/v1/events accepts none (user chose this over extending the backend). Signed-out hosts are detected by a 401 and sent to /auth/login?next=..., because there is no session-check endpoint; the typed form is lost on that bounce. Components are unit-tested with mocked API modules; the real sign-in path was not exercised end to end (no Redis/Mailpit). Review fixes: 15 s request timeout, hidden reveal delay reset, no duplicate create after a failed navigation, reload on route id change. A real-browser check found resolve.conditions: [] in vite.config.ts broke onMount in dev and build (fixed, regression test src/config.test.ts). | G5: 64bb0d2 e22fc04 840a9e6 abfcf99 9718420 2185cb4 deb9be8 a625187 d205277 532c966 d1100f0 94f617f 1d11def 41bd0e7 7e82db3 1b66d55 63cce8a e89ee60 | H5: 2026-09-20
A6: Milestone 1: Host creates an event | B6: apps/web (tests/e2e), scripts | C6: T7.1 | D6: Added Playwright end-to-end tests that drive Chrome through the Vite proxy to the real API, Postgres, Redis and Mailpit (scripts/e2e.sh), and made scripts/check.sh run them; timed the scripted host flow against the 3-minute target. | E6: scripts/check.sh now needs Docker (Redis + Mailpit up), Chrome and TEST_DATABASE_URL; SKIP_E2E=1 skips the e2e step with a loud notice. Port 8080 is held by an unrelated Apache service on the dev machine, so e2e uses 8081/9091/5174. | F6: Installed Chrome instead of downloading Playwright browsers; e2e uses a throwaway sela_e2e_<pid> database on the local Postgres and resets only rl:/attempts:/lock: keys on the compose Redis; one unique email per test because of the OTP rate limits; the QR PNG is decoded with jsqr to prove it encodes the short link; scripted time is a lower bound and not the PRD metric. A typescript review found no CRITICAL/HIGH; the MEDIUMs (unguarded database-URL rewrite, unchecked Redis container, one-shot QR load check) were fixed in 7b11984. Also added .gitattributes so shell scripts keep LF. | G6: 58b435f 56159ff 29d31b5 70c75d0 fcdfe29 44e0983 6037092 d34c798 96d0a2a 7b11984 | H6: 2026-09-20
A7: Milestone 1: Host creates an event | B7: cmd/api | C7: T3.7 | D7: Wired config, Postgres, Redis, SMTP and the auth service into one process serving HTTP and gRPC, with an end-to-end test. | E7: cmd/api's run() now takes (ctx, getenv); the server no longer starts without the required environment. | F7: Services stay packages in one process (deviation from separate deployables, recorded in FSD 2.6). go test -race unavailable locally (needs cgo/gcc); run it in CI. | G7: 5a3dbe0 2bffd81 578bab2 218243d 573d78f | H7: 2026-09-19
A8: Milestone 1: Host creates an event | B8: cmd/migrate | C8: T3.1 | D8: Added a CLI that applies (up) or reverts (down) migrations against DATABASE_URL. | E8: None. | F8: Default command is up; DSN is never printed; run() is injectable for tests. | G8: f5935c9 a1e047f b2ef0ef | H8: 2026-09-19
A9: Milestone 1: Host creates an event | B9: deploy, cmd/api | C9: T3.8 | D9: Verified the email OTP flow live against docker compose Redis and Mailpit with the real API; all checks passed without service changes. | E9: None. | F9: Verification lives in apps/web/tests/e2e/auth-live.spec.ts so it is repeatable; compose's postgres was not used because a local PostgreSQL 17 owns 5432. | G9: n/a (verification; tests in 44e0983) | H9: 2026-09-20
A10: Milestone 1: Host creates an event | B10: deploy, scripts/check.sh | C10: T1.3 | D10: Added Docker Compose services (Postgres, Redis, Mailpit) bound to localhost with required credentials, .env.example and scripts/check.sh. | E10: None. | F10: Compose refuses to start without credentials; check.sh became the single validation entrypoint. | G10: 20ade0e cbeb530 | H10: 2026-09-19
A11: Milestone 1: Host creates an event | B11: docs | C11: T3.9 | D11: Updated the FSD to v2.5 and created this tracker with its build script and process. | E11: None. | F11: PRD and BRD intentionally unchanged: implementation so far does not change product scope, and their documented inconsistencies (MVP category count, free-tier watermark, BR-17 numbering) stay open. docs/ is gitignored, so these updates are not in commits. | G11: n/a | H11: 2026-09-19
A12: Milestone 1: Host creates an event | B12: docs | C12: T4.4 | D12: Updated the FSD to v2.6 and this tracker for Task 4. | E12: None. | F12: PRD and BRD still unchanged; the fallback defaults are recorded in FSD 4.1 as derived from BRD 7/10 for product review. | G12: n/a | H12: 2026-09-20
... A26: Milestone 8: RBAC foundation (cross-cutting platform work) | B26: internal/db, services/rbac, services/event, cmd/api | C26: T9.1 | D26: Implemented the RBAC foundation for real: migrations for roles/menus/dropdowns/actions/permissions, a services/rbac package (Postgres repository, Service resolving per-role menus/actions/dropdowns/preferences with a host-then-role-then-global fallback chain), GET /api/v1/auth/me and PATCH /api/v1/me/preferences, and events:create enforcement on the already-shipped POST /api/v1/events. | E26: POST /api/v1/events now requires the events:create permission in addition to a host session; every existing host is granted it by default in the seed, so behavior is unchanged unless a permission is explicitly revoked. | F26: Fallback-chain and ancestor-inclusion logic lives in Go (table-driven tested), not PL/pgSQL, matching this codebase's zero-stored-procedure convention; the one exception is a menu cycle-prevention trigger, a genuine data-integrity invariant a CHECK can't express. Seed data stays minimal and real: 2 flat menus (events_new, settings), 2 enforced permissions (events:create, profile:update); dropdowns and nested menus are schema-complete and tested but unseeded, since no real consumer exists yet. REST only, no gRPC, for /auth/me (fast-follow, mirrors Task 5's precedent). No permission-check caching (single API instance). | G26: 85ac425 cf5f3a8 e76992d b85cbb8 08d0812 1bc1ec4 68ae150 bb79173 | H26: 2026-09-23

Sheet Traceability
A1: FR ID | B1: Requirement (from FSD) | C1: FSD section | D1: Milestone | E1: Status | F1: Tracker task(s) | G1: Evidence
A2: FR-01.1 | B2: Sistem menyediakan daftar kategori acara dengan template tema & pengaturan default masing-masing. | C2: 4.1 | D2: Milestone 1: Host creates an event | E2: Completed | F2: T2.1, T4.1, T4.2, T6.1 | G2: category presets with effective defaults over REST and gRPC; host category picker at /events/new shows each preset's defaults (category default numbers are still tbd, awaiting product)
A3: FR-01.2 | B3: Sistem menyediakan formulir pembuatan event minimal (nama, tanggal) dengan field lain opsional. | C3: 4.1 | D3: Milestone 1: Host creates an event | E3: Completed | F3: T2.1, T4.1, T4.2, T6.1 | G3: create-event API with validation; host form at /events/new with name and date required and overrides collapsed; time zone shown read-only as WIB because the API takes none
A4: FR-01.3 | B4: Sistem menghasilkan QR code unik dan tautan pendek (short link) per event. | C4: 4.1 | D4: Milestone 1: Host creates an event | E4: Completed | F4: T2.1, T4.1, T4.2, T5.1, T6.1 | G4: unique short_code, short_link = base/e/code, owner-only QR PNG/SVG, public GET /e/{short_code} resolver (guest-safe metadata, identical 404s); host result screen /events/[id] with copy link and PNG/SVG download
A5: FR-01.4 | B5: Sistem menyimpan konfigurasi jumlah jepretan maksimum (termasuk opsi tak terbatas) dan mode reveal per event. | C5: 4.1 | D5: Milestone 1: Host creates an event | E5: Completed | F5: T2.1, T4.1, T4.2 | G5: shot_limit (NULL/0 = unlimited), reveal_mode and reveal_at stored per event; per-category numeric defaults remain tbd pending product
A6: FR-01.5 | B6: Sistem merekomendasikan paket berdasarkan kategori & estimasi skala acara, namun tetap dapat diubah bebas oleh host. | C6: 4.1 | D6: Milestone 5: Plans and payment | E6: Not Started | F6: M5.1
A7: FR-01.6 | B7: Sistem mengintegrasikan payment gateway untuk paket berbayar, termasuk nominal mikro (QRIS, e-wallet, kartu). | C7: 4.1 | D7: Milestone 5: Plans and payment | E7: Not Started | F7: M5.1
A8: FR-02.1 | B8: Sistem memvalidasi token event dari QR/tautan sebelum menampilkan kamera. | C8: 4.2 | D8: Milestone 2: Guest captures and uploads | E8: Not Started
A9: FR-02.2 | B9: Sistem membuat & menyimpan guest session ID unik per perangkat/browser (jika event menerapkan batas jepretan). | C9: 4.2 | D9: Milestone 2: Guest captures and uploads | E9: Not Started
A10: FR-02.3 | B10: Sistem menampilkan pesan status sesuai kondisi event (belum mulai/aktif/berakhir). | C10: 4.2 | D10: Milestone 2: Guest captures and uploads | E10: Not Started
A11: FR-02.4 | B11: Sistem menampilkan tema visual kamera sesuai kategori acara terkait. | C11: 4.2 | D11: Milestone 2: Guest captures and uploads | E11: Not Started
A12: FR-03.1 | B12: Sistem menyediakan akses kamera perangkat via Web API (getUserMedia) dengan fallback unggah manual. | C12: 4.3 | D12: Milestone 2: Guest captures and uploads | E12: Not Started
A13: FR-03.2 | B13: Sistem menerapkan filter visual sesuai tema kategori acara yang dipilih host. | C13: 4.3 | D13: Milestone 2: Guest captures and uploads | E13: Not Started
A14: FR-03.3 | B14: Sistem menegakkan (atau membebaskan) batas jumlah jepretan per sesi tamu sesuai konfigurasi event. | C14: 4.3 | D14: Milestone 2: Guest captures and uploads | E14: Not Started
A15: FR-03.4 | B15: Sistem mengantrekan unggahan secara offline-first saat koneksi tidak stabil. | C15: 4.3 | D15: Milestone 2: Guest captures and uploads | E15: Not Started
A16: FR-03.5 | B16: Sistem menyediakan pilihan format kolase/strip photobooth dengan hitung mundur & burst capture otomatis. | C16: 4.3 | D16: Milestone 2: Guest captures and uploads | E16: Not Started
A17: FR-03.6 | B17: Sistem membatasi kustomisasi tampilan hasil pada layout, warna aksen, dan teks singkat saja (tanpa editor bebas). | C17: 4.3 | D17: Milestone 2: Guest captures and uploads | E17: Not Started
A18: FR-04.1 | B18: Sistem mendukung unggah multi-file dengan validasi format (JPEG/PNG/HEIC, MP4/MOV) dan batas ukuran. | C18: 4.4 | D18: Milestone 2: Guest captures and uploads | E18: Not Started
A19: FR-04.2 | B19: Sistem menyediakan toggle host untuk mengaktifkan/menonaktifkan unggah galeri per event. | C19: 4.4 | D19: Milestone 2: Guest captures and uploads | E19: Not Started
... A34: FR-08.2 | B34: Sistem mencatat preferensi opt-in/opt-out notifikasi per kontak. | C34: 4.8 | D34: Backlog: Should-have and later phases | E34: Not Started
A35: FR-09.1 | B35: Sistem menyediakan autentikasi berbasis OTP (email/SMS). | C35: 4.9 | D35: Milestone 1: Host creates an event | E35: Partial | F35: T3.3, T3.5, T3.6, T3.7, T3.8, T6.1, T7.1 | G35: email OTP over REST and gRPC; host sign-in page /auth/login (two steps, localised errors, rate-limit and lockout wait); verified live against real Redis and Mailpit (T3.8, T7.1); SMS not implemented
A36: FR-09.2 | B36: Sistem mengintegrasikan payment gateway lokal (QRIS, e-wallet, kartu) yang mendukung nominal mikro. | C36: 4.9 | D36: Milestone 5: Plans and payment | E36: Not Started | F36: M5.1
A37: FR-09.3 | B37: Sistem mencatat riwayat transaksi & status langganan per host. | C37: 4.9 | D37: Milestone 5: Plans and payment | E37: Not Started | F37: M5.1
A38: FR-10.1 | B38: Sistem menyediakan jalur "Capture Langsung" dari halaman utama tanpa mewajibkan pembuatan event. | C38: 4.10 | D38: Backlog: Should-have and later phases | E38: Not Started
A39: FR-10.2 | B39: Sistem memproses hasil secara instan/sinkron untuk mode ini (target \< beberapa detik). | C39: 4.10 | D39: Backlog: Should-have and later phases | E39: Not Started
A40: FR-10.3 | B40: Sistem mendukung pengiriman ke banyak alamat email sekaligus dalam satu aksi. | C40: 4.10 | D40: Backlog: Should-have and later phases | E40: Not Started
A41: FR-10.4 | B41: Sistem menghasilkan tautan unduh bertoken unik dan/atau QR sekali pakai dengan masa berlaku terbatas. | C41: 4.10 | D41: Backlog: Should-have and later phases | E41: Not Started
A42: FR-10.5 | B42: Sistem menetapkan masa simpan hasil berdasarkan status akun (7 hari anonim / 30 hari login / permanen berbayar) dan menjalankan job penghapusan otomatis saat kedaluwarsa. | C42: 4.10 | D42: Backlog: Should-have and later phases | E42: Not Started
A43: FR-10.6 | B43: Sistem mengaitkan hasil anonim ke akun pengguna saat pengguna login, beserta perpanjangan masa simpannya. | C43: 4.10 | D43: Backlog: Should-have and later phases | E43: Not Started
A44: FR-10.7 | B44: Sistem mengirim notifikasi sebelum hasil kedaluwarsa beserta opsi memperpanjang (login atau upgrade berbayar). | C44: 4.10 | D44: Backlog: Should-have and later phases | E44: Not Started
A45: FR-11.1 | B45: Sistem menyediakan aksi tandai/lepas tanda Hall of Fame per item media bagi host. | C45: 4.11 | D45: Backlog: Should-have and later phases | E45: Not Started
A46: FR-11.2 | B46: Sistem menyediakan halaman Hall of Fame dengan tautan berbagi tersendiri. | C46: 4.11 | D46: Backlog: Should-have and later phases | E46: Not Started
A47: FR-11.3 | B47: Sistem mendukung pengaturan ulang urutan tampilan item Hall of Fame. | C47: 4.11 | D47: Backlog: Should-have and later phases | E47: Not Started
A48: FR-11.4 | B48: Sistem otomatis mengeluarkan media dari Hall of Fame bila media tersebut dihapus/disembunyikan. | C48: 4.11 | D48: Backlog: Should-have and later phases | E48: Not Started
A49: FR-11.5 | B49: (Opsional) Sistem menyediakan daftar kandidat berdasarkan jumlah reaksi tamu sebagai saran kurasi. | C49: 4.11 | D49: Backlog: Should-have and later phases | E49: Not Started
... A52: FR-SEC.3 | B52: Sistem memvalidasi tipe berkas unggahan berdasarkan magic bytes dan menolak berkas yang tidak sesuai. | C52: 8.12 | D52: Milestone 6: Privacy and compliance readiness | E52: Not Started
A53: FR-SEC.4 | B53: Sistem menyimpan token pada cookie HttpOnly + Secure + SameSite dan menyediakan mekanisme pencabutan token. | C53: 8.12 | D53: Milestone 1: Host creates an event | E53: Partial | F53: T3.5, T3.6, T3.10 | G53: HttpOnly/SameSite cookie, hashed expiring tokens; refresh and revocation pending
A54: FR-SEC.5 | B54: Sistem mengenkripsi kolom PII (email, nomor HP) pada PostgreSQL dengan kunci terpisah dari kunci media. | C54: 8.12 | D54: Milestone 6: Privacy and compliance readiness | E54: Not Started | F54: M6.1
A55: FR-SEC.6 | B55: Sistem mencatat audit log append-only untuk seluruh aksi sensitif tanpa memuat PII/token mentah. | C55: 8.12 | D55: Milestone 6: Privacy and compliance readiness | E55: Not Started
A56: FR-SEC.7 | B56: Sistem memungkinkan pemilik event mencabut tautan/QR event maupun tautan berbagi yang telah dibuat. | C56: 8.12 | D56: Milestone 6: Privacy and compliance readiness | E56: Not Started
...
